<sdf version='1.9'>
  <model name="double_pendulum_with_base">
      <link name="base">
        <inertial>
          <mass>100</mass>
        </inertial>
        <visual name="vis_plate_on_ground">
          <pose>0 0 0.01 0 0 0</pose>
          <geometry>
            <cylinder>
              <radius>0.8</radius>
              <length>0.02</length>
            </cylinder>
          </geometry>
          <material>
            <ambient>0.8 0.8 0.8 1</ambient>
            <diffuse>0.8 0.8 0.8 1</diffuse>
            <specular>0.8 0.8 0.8 1</specular>
          </material>
        </visual>
        <visual name="vis_pole">
          <pose>-0.275 0 1.1 0 0 0</pose>
          <geometry>
            <box>
              <size>0.2 0.2 2.2</size>
            </box>
          </geometry>
          <material>
            <ambient>0.8 0.8 0.8 1</ambient>
            <diffuse>0.8 0.8 0.8 1</diffuse>
            <specular>0.8 0.8 0.8 1</specular>
          </material>
        </visual>
        <collision name="col_plate_on_ground">
          <pose>0 0 0.01 0 0 0</pose>
          <geometry>
            <cylinder>
              <radius>0.8</radius>
              <length>0.02</length>
            </cylinder>
          </geometry>
        </collision>
        <collision name="col_pole">
          <pose>-0.275 0 1.1 0 0 0</pose>
          <geometry>
            <box>
              <size>0.2 0.2 2.2</size>
            </box>
          </geometry>
        </collision>
      </link>
      <!-- upper link, length 1, IC -90 degrees -->
      <link name="upper_link">
        <pose>0 0 2.1 -1.5708 0 0</pose>
        <self_collide>0</self_collide>
        <inertial>
          <pose>0 0 0.5 0 0 0</pose>
          <mass>1.0129999999999999</mass>
          <inertia>
          <ixx>0.0055290649999999997</ixx>
          <ixy>-4.8250000000000004e-06</ixy>
          <ixz>0.00034386900000000001</ixz>
          <iyy>0.0051393389999999997</iyy>
          <iyz>-2.2447999999999999e-05</iyz>
          <izz>0.001367788</izz>
          </inertia>
        </inertial>
        <visual name="vis_upper_joint">
          <pose>-0.05 0 0 0 1.5708 0</pose>
          <geometry>
            <cylinder>
              <radius>0.1</radius>
              <length>0.3</length>
            </cylinder>
          </geometry>
          <material>
            <ambient>0.8 0.8 0.8 1</ambient>
            <diffuse>0.8 0.8 0.8 1</diffuse>
            <specular>0.8 0.8 0.8 1</specular>
          </material>
        </visual>
        <visual name="vis_lower_joint">
          <pose>0 0 1.0 0 1.5708 0</pose>
          <geometry>
            <cylinder>
              <radius>0.1</radius>
              <length>0.2</length>
            </cylinder>
          </geometry>
          <material>
            <ambient>0.8 0.8 0.8 1</ambient>
            <diffuse>0.8 0.8 0.8 1</diffuse>
            <specular>0.8 0.8 0.8 1</specular>
          </material>
        </visual>
        <visual name="vis_cylinder">
          <pose>0 0 0.5 0 0 0</pose>
          <geometry>
            <cylinder>
              <radius>0.1</radius>
              <length>0.9</length>
            </cylinder>
          </geometry>
          <material>
            <ambient>0.8 0.8 0.8 1</ambient>
            <diffuse>0.8 0.8 0.8 1</diffuse>
            <specular>0.8 0.8 0.8 1</specular>
          </material>
        </visual>
        <collision name="col_upper_joint">
          <pose>-0.05 0 0 0 1.5708 0</pose>
          <geometry>
            <cylinder>
              <radius>0.1</radius>
              <length>0.3</length>
            </cylinder>
          </geometry>
        </collision>
        <collision name="col_lower_joint">
          <pose>0 0 1.0 0 1.5708 0</pose>
          <geometry>
            <cylinder>
              <radius>0.1</radius>
              <length>0.2</length>
            </cylinder>
          </geometry>
        </collision>
        <collision name="col_cylinder">
          <pose>0 0 0.5 0 0 0</pose>
          <geometry>
            <cylinder>
              <radius>0.1</radius>
              <length>0.9</length>
            </cylinder>
          </geometry>
        </collision>
      </link>
      <!-- lower link, length 1, IC ~-120 degrees more -->
      <link name="lower_link">
        <pose>0.25 1.0 2.1 -2 0 0</pose>
        <self_collide>0</self_collide>
        <inertial>
          <pose>0 0 0.5 0 0 0</pose>
          <mass>0.22600000000000001</mass>
          <inertia>
          <ixx>0.003385566451939115</ixx>
          <ixy>0</ixy>
          <ixz>-0.00016742735341238941</ixz>
          <iyy>0.0034034413894656651</iyy>
          <iyz>0</iyz>
          <izz>4.3850937526548672e-05</izz>
          </inertia>
        </inertial>
        <visual name="vis_lower_joint">
          <pose>0 0 0 0 1.5708 0</pose>
          <geometry>
            <cylinder>
              <radius>0.08</radius>
              <length>0.3</length>
            </cylinder>
          </geometry>
          <material>
            <ambient>0.8 0.8 0.8 1</ambient>
            <diffuse>0.8 0.8 0.8 1</diffuse>
            <specular>0.8 0.8 0.8 1</specular>
          </material>
        </visual>
        <visual name="vis_cylinder">
          <pose>0 0 0.5 0 0 0</pose>
          <geometry>
            <cylinder>
              <radius>0.1</radius>
              <length>0.9</length>
            </cylinder>
          </geometry>
          <material>
            <ambient>0.8 0.8 0.8 1</ambient>
            <diffuse>0.8 0.8 0.8 1</diffuse>
            <specular>0.8 0.8 0.8 1</specular>
          </material>
        </visual>
        <collision name="col_lower_joint">
          <pose>0 0 0 0 1.5708 0</pose>
          <geometry>
            <cylinder>
              <radius>0.08</radius>
              <length>0.3</length>
            </cylinder>
          </geometry>
        </collision>
        <collision name="col_cylinder">
          <pose>0 0 0.5 0 0 0</pose>
          <geometry>
            <cylinder>
              <radius>0.1</radius>
              <length>0.9</length>
            </cylinder>
          </geometry>
        </collision>
      </link>
      <!-- pin joint for upper link, at origin of upper link -->
      <joint name="upper_joint" type="revolute">
        <parent>base</parent>
        <child>upper_link</child>
        <axis>
          <xyz>1.0 0 0</xyz>
        </axis>
      </joint>
      <!-- pin joint for lower link, at origin of child link -->
      <joint name="lower_joint" type="revolute">
        <parent>upper_link</parent>
        <child>lower_link</child>
        <axis>
          <xyz>1.0 0 0</xyz>
        </axis>
      </joint>
    </model>
</sdf>
